<?xml version="1.0"?>
<robot name="custom_robot_3">
    <link name="base_link">
        <visual>
            <geometry>
                <box size="0.4 0.3 0.1"/>
            </geometry>
            <material name="red">
                <color rgba="1 0.0 0.0 1"/>
            </material>
        </visual>

        <collision>
            <geometry>
                <box size="0.4 0.3 0.1"/>
            </geometry>
        </collision>
        
        <inertial>
            <mass value="1.0"/>
            <inertia ixx="0.015" ixy="0" ixz="0" iyy="0.0375" iyz="0.0" izz="0.0375"/>
        </inertial>
    </link>
    
    <link name="front_caster_of_wheel">
        <visual>
            <geometry>
                <box size="0.1 0.1 0.1"/>
            </geometry>
            <material name="green">
                <color rgba="0.0 0.1 0.0 1"/>
            </material>
        </visual>
        
        <collision>
            <geometry>
                <box size="0.1 0.1 0.1"/>
            </geometry>
        </collision>
        
        <inertial>
            <mass value="0.1"/>
            <inertia ixx="0.00083" ixy="0" ixz="0" iyy="0.00083" iyz="0.0" izz="0.000167"/>
        </inertial>
    </link>
    
    <joint name="front_caster_of_wheel_joint" type="fixed"> <!-- continuous -->
        <axis xyz="0.0 0.0 1"/>
        <parent link="base_link"/>
        <child link="front_caster_of_wheel"/>
        <origin xyz="0.15 0.0 0.0" rpy="0.0 0.0 0.0"/>
    </joint>
    
    <link name="front_wheel">
        <visual>
            <geometry>
                <cylinder radius="0.035" length="0.05"/>
            </geometry>
            <material name="black">
                <color rgba="0.0 0.1 0.0 1"/>
            </material>
        </visual>
        
        <collision>
            <geometry>
                <cylinder radius="0.035" length="0.05"/>
            </geometry>
        </collision>
        
        <inertial>
            <mass value="0.1"/>
            <inertia ixx="5.1458e-5" ixy="0" ixz="0" iyy="5.1458e-5" iyz="0.0" izz="6.125e-5"/>
        </inertial>
    </link>

    <joint name="front_wheel_joint" type="fixed">  <!-- continuous -->
        <axis xyz="0.0 0.0 1"/>
        <parent link="front_caster_of_wheel"/>
        <child link="front_wheel"/>
        <origin xyz="0.05 0.0 -0.05" rpy="-1.5708 0.0 0.0"/>
    </joint>
    
    <link name="right_wheel">
        <visual>
            <geometry>
                <cylinder radius="0.035" length="0.05"/>
            </geometry>
            <material name="black">
                <color rgba="0.0 0.0 0.0 1"/>
            </material>
        </visual>
        
        <collision>
            <geometry>
                <cylinder radius="0.035" length="0.05"/>
            </geometry>
        </collision>
        
        <inertial>
            <mass value="0.1"/>
            <inertia ixx="5.1458e-5" ixy="0" ixz="0" iyy="5.1458e-5" iyz="0.0" izz="6.125e-5"/> 
        </inertial>
    </link>
    
    <joint name="right_wheel_joint" type="continuous">
        <axis xyz="0.0 0.0 1"/>
        <parent link="base_link"/>
        <child link="right_wheel"/>
        <origin xyz="-0.1825 -0.125 -0.05" rpy="-1.5708 0.0 0.0"/>
        <!-- x = -0.2825 -->
    </joint>
    
    <link name="left_wheel">
        <visual>
            <geometry>
                <cylinder radius="0.035" length="0.05"/>
            </geometry>
            <material name="black">
                <color rgba="0.0 0.0 0.0 1"/>
            </material>
        </visual>

        <collision>
            <geometry>
                <cylinder radius="0.035" length="0.05"/>
            </geometry>
        </collision>
    
        <inertial>
            <mass value="0.1"/>
            <inertia ixx="5.1458e-5" ixy="0" ixz="0" iyy="5.1458e-5" iyz="0.0" izz="6.125e-5"/>
        </inertial>
    </link>

    <joint name="left_wheel_joint" type="continuous">
        <axis xyz="0.0 0.0 1"/>
        <parent link="base_link"/>
        <child link="left_wheel"/>
        <origin xyz="-0.1825 0.125 -0.05" rpy="-1.5708 0.0 0.0"/>
        <!-- x = -0.2825 -->
    </joint>

    <link name="thermal_frame">
        <visual>
            <geometry>
                <cylinder radius="0.025" length="0.07"/>
                <!-- <box size="0.05 0.05 0.05"/> -->
            </geometry>
        </visual>
        
        <collision>
            <geometry>
                <box size="0.1 0.1 0.1"/>
            </geometry>
        </collision>

        <inertial>
            <mass value="1e-3"/>
            <inertia ixx="1e-5" ixy="0" ixz="0.0" iyy="1e-5" iyz="0.0" izz="1e-5"/>
        </inertial>
    </link>

    <joint name="thermal_joint" type="fixed">
        <axis xyz="0.0 0.0 1.0"/>
        <origin xyz="0.17 0.0 0.075" rpy="0.0 0.0 0.0"/>
        <parent link="base_link"/>
        <child link="thermal_frame"/>
        <axis xyz="0.0 0.0 0.0"/>
        <limit lower="0.0" upper="0.0" effort="0.0" velocity="0.0"/>
    </joint>

    <link name="laser_scanner"/>
    <joint name="laser_joint" type="fixed">
        <parent link="base_link"/>
        <child link="laser_scanner"/>
        <origin xyz="0.0 0.0 0.0" rpy="0.0 0.0 0.0"/>
    </joint>
    

    <!-- <transmission name="laser_joint_trans" type="SimpleTransmission">
        <type>transmission_interface/SimpleTransmission</type>
        <actuator name="laser_joint_motor">
            <hardwareInterface>hardware_interface/EffortJointInterface</hardwareInterface>
            <mechanicalReduction>1</mechanicalReduction>
        </actuator>
        <joint name="laser_joint">
            <hardwareInterface>hardware_interface/EffortJointInterface</hardwareInterface>
        </joint>
    </transmission> -->


    <gazebo>
        <plugin name="differential_drive_controller"
            filename="libgazebo_ros_diff_drive.so">
            <legacyMode>false</legacyMode>
            <alwaysOn>true</alwaysOn>
            <updateRate>20</updateRate>
            <leftJoint>left_wheel_joint</leftJoint>
            <rightJoint>right_wheel_joint</rightJoint>
            <robotBaseFrame>base_link</robotBaseFrame>
            <wheelSeparation>0.25</wheelSeparation>
            <wheelDiameter>0.07</wheelDiameter>
            <wheelTorque>0.1</wheelTorque>
            <commandTopic>cmd_vel</commandTopic>
            <odometryTopic>odom</odometryTopic>
            <odometryFrame>odom</odometryFrame>
            <publishWheelJointState>true</publishWheelJointState>
            <publishOdomTF>true</publishOdomTF>
        </plugin>
    </gazebo>
    <gazebo reference="thermal_frame">
        <sensor type="camera" name="thermal_camera_sensor">
            <updateRate>10</updateRate>
            <camera name="thermal_camera">
                <horizontal_fov> 1.3962634 </horizontal_fov>
                <image>
                    <width> 160 </width>
                    <height> 120 </height>
                    <format>R8G8B8</format>
                </image>
                <clip>
                    <near> 0.01 </near>
                    <far> 100 </far>
                </clip>
                <noise>
                    <type> gaussian </type>
                    <mean> 0.0 </mean>
                    <stddev> 0.007 </stddev>
                </noise>
            </camera>
            <plugin name="thermal_camera_controller" filename="libgazebo_ros_camera.so">
                <alwaysOn>true</alwaysOn>
                <updateRate>10</updateRate>
                <imageTopicName>/thermal_camera/image_raw</imageTopicName>
                <cameraInfoTopicName>/thermal_camera/camera_info</cameraInfoTopicName>
                <frameName>thermal_optical_frame</frameName>
                <hackBaseline>0.07</hackBaseline>
                <distortionK1>0.0</distortionK1>
                <distortionK2>0.0</distortionK2>
                <distortionK3>0.0</distortionK3>
                <distortionT1>0.0</distortionT1>
                <distortionT2>0.0</distortionT2>
            </plugin>
        </sensor>
    </gazebo>
    <gazebo reference="laser_scanner">
        <sensor type="ray" name="head_hokuyo_sensor">
            <pose>-0.18 0 0 0 0 0</pose>
            <visualize>true</visualize>
            <update_rate>40</update_rate>
            <ray>
                <scan>
                    <horizontal>
                        <samples>180</samples>
                        <resolution>1</resolution>
                        <min_angle>-0.31</min_angle>
                        <max_angle>0.31</max_angle>
                    </horizontal>
                </scan>
                <range>
                    <min>0.4</min>
                    <max>1.35</max>
                    <resolution>0.01</resolution>
                    <!-- <resolution>0.003</resolution> -->
                </range>
                <noise>
                    <type>gaussian</type>
                    <mean>0.0</mean>
                    <stddev>0.01</stddev>
                </noise>
            </ray>
            <plugin name="gazebo_ros_head_hokuyo_controller" filename="libgazebo_ros_laser.so">
                <topicName>LaserScan</topicName>
                <frameName>laser_scanner</frameName>
            </plugin>
        </sensor>
    </gazebo>
    <gazebo reference="front_wheel">
        <material>Gazebo/Black</material>
        <mu1>0.0</mu1>
        <mu2>0.0</mu2>
        <selfCollide>false</selfCollide>
    </gazebo>
    <gazebo reference="right_wheel">
        <material>Gazebo/Black</material>
    </gazebo>
    <gazebo reference="left_wheel">
        <material>Gazebo/Black</material>
    </gazebo>
    <gazebo reference="base_link">
        <material>Gazebo/Yellow</material>
        <mu1>0.01</mu1>
        <mu2>0.01</mu2>
    </gazebo>
    <gazebo>
        <plugin name="gazebo_ros_control" filename="libgazebo_ros_control.so">
            <!-- <robotNamespace>/</robotNamespace> -->
            <controlPeriod>0.001</controlPeriod>
            <legacyModeNS>false</legacyModeNS>
        </plugin>
    </gazebo>
    <gazebo>
        <plugin name="joint_state_publisher"
            filename="libgazebo_ros_joint_state_publisher.so">
            <jointName>left_wheel_joint, right_wheel_joint</jointName> 
            <!-- , laser_joint</jointName>  -->
            <!-- front_caster_of_wheel_joint, front_wheel_joint -->
        </plugin>
    </gazebo>
</robot>